# issue #332: Ansible 2.6 file.py started defining an excepthook and private
# AnsibleModuleError. Ensure file fails correctly.

- name: regression/issue_332_ansiblemoduleerror_first_occurrence.yml
  hosts: test-targets
  tasks:
  - file: path=/usr/bin/does-not-exist mode='a-s' state=file follow=yes
    ignore_errors: true
    register: out

  - assert:
      that:
        - out.msg == 'file (/usr/bin/does-not-exist) is absent, cannot continue'
      fail_msg: out={{out}}
  tags:
    - issue_332
